Workbook

Sheet Base
A1: Área | B1: PAGAMENTO | C1: Fornecedor | D1: Motivo | E1: Fixo/Varíavel | F1: EDOA
A2: Acordo Projeto SAC | B2: Adiantamento | C2: Escritório Alfa Advogados | D2: Acordo | E2: Fixo | F2: CARTÓRIO
A3: Cartório | B3: Interno | C3: Beta & Associados | D3: Projuris | E3: Fixo valor variável | F3: Depósito Judicial
A4: Cível | C4: Gama Consultoria Jurídica | D4: Condenação | E4: Variável pontual | F4: HONORÁRIOS E DESPESAS
A5: Consumidor | C5: Delta Advocacia | D5: Custas | F5: LGPD GERAL & TERCEIROS
A6: LGPD | D6: Depósito Judicial | F6: OUTRA ÁREA
A7: Trabalhista | D7: Despesas | F7: OUTROS (Jurídico)
A8: Tributário | D8: Honorários | F8: CORPORATE
A9: Societário | D9: Juros e correção | F9: ACORDOS CONSUMIDOR
A10: Rede | D10: LGPD | F10: ACORDOS SAC
A11: Serviços terceirizados | F11: TRABALHISTA GERAL
A12: Projuris SUPRAMONTE | F12: TRABALHISTA ACORDOS
F13: PIF/PDV
F14: SISTEMAS

Sheet Resultado
B1: APENAS UM FILTRO POR MESES
B2: MÊS | C2: Março
B4: CATEGORIA | C4: DOA | D4: PERÍODO | E4: IMPACTO | F4: R$ GASTO MENSAL | G4: R$ GASTO ANUAL
B5: RDB - CONS | C5: ACORDOS CONSUMIDOR + SAC | D5: =$C$2 | E5: APCO
B6: RDB - CONS | C6: CORPORATE | D6: =$C$2 | E6: APCO | F6: =SUMIFS('Controle Lançamentos'!G:G,'Controle Lançamentos'!B:B,B6,'Controle Lançamentos'!H:H,D6,'Controle Lançamentos'!Q:Q,Resultado!C6) | G6: =SUMIFS('Controle Lançamentos'!G:G,'Controle Lançamentos'!B:B,B6,'Controle Lançamentos'!Q:Q,Resultado!C6)
B7: RDB - CONS | C7: HONORÁRIOS E DESPESAS | D7: =$C$2 | E7: G&A | F7: =SUMIFS('Controle Lançamentos'!G:G,'Controle Lançamentos'!B:B,B7,'Controle Lançamentos'!H:H,D7,'Controle Lançamentos'!Q:Q,Resultado!C7) | G7: =SUMIFS('Controle Lançamentos'!G:G,'Controle Lançamentos'!B:B,B7,'Controle Lançamentos'!Q:Q,Resultado!C7)
B8: RDB - TRAB CVP | C8: TRABALHISTA GERAL | D8: =$C$2 | E8: MASSA | F8: =SUMIFS('Controle Lançamentos'!G:G,'Controle Lançamentos'!B:B,B8,'Controle Lançamentos'!H:H,D8,'Controle Lançamentos'!Q:Q,Resultado!C8) | G8: =SUMIFS('Controle Lançamentos'!G:G,'Controle Lançamentos'!B:B,B8,'Controle Lançamentos'!Q:Q,Resultado!C8)
B9: RDB - TRAB SUPORTE | C9: TRABALHISTA ACORDOS | D9: =$C$2 | E9: G&A | F9: =SUMIFS('Controle Lançamentos'!G:G,'Controle Lançamentos'!B:B,B9,'Controle Lançamentos'!H:H,D9,'Controle Lançamentos'!Q:Q,Resultado!C9) | G9: =SUMIFS('Controle Lançamentos'!G:G,'Controle Lançamentos'!B:B,B9,'Controle Lançamentos'!Q:Q,Resultado!C9)
B10: RDB - TRAB PIF | C10: PIF/PDV | D10: =$C$2 | E10: APCE | F10: =SUMIFS('Controle Lançamentos'!G:G,'Controle Lançamentos'!B:B,B10,'Controle Lançamentos'!H:H,D10,'Controle Lançamentos'!Q:Q,Resultado!C10) | G10: =SUMIFS('Controle Lançamentos'!G:G,'Controle Lançamentos'!B:B,B10,'Controle Lançamentos'!Q:Q,Resultado!C10)
B11: RDB - TRIB | C11: CORPORATE | D11: =$C$2 | E11: APCO | F11: =SUMIFS('Controle Lançamentos'!G:G,'Controle Lançamentos'!B:B,B11,'Controle Lançamentos'!H:H,D11,'Controle Lançamentos'!Q:Q,Resultado!C11) | G11: =SUMIFS('Controle Lançamentos'!G:G,'Controle Lançamentos'!B:B,B11,'Controle Lançamentos'!Q:Q,Resultado!C11)
B12: Juros e correção | D12: =$C$2 | E12: Juros e correção
G14: =SUM(G6:G11)

Sheet LGPD
A2: EDOA | B2: LGPD GERAL & TERCEIROS
A4: Soma de Valor | B4: Rótulos de Coluna
A5: Rótulos de Linha | B5: Fixo | C5: Variável pontual | D5: Total Geral

Sheet Controle Lançamentos
A1: STATUS | B1: CATEGORIA | C1: ÁREA | D1: PAGAMENTO | E1: REFERÊNCIA | F1: MOTIVO | G1: Valor | H1: MÊS REFERENCIA | I1: DATA PAGAMENTO | J1: RECORRÊNCIA | K1: DESCRIÇÃO | L1: RC | M1: Nº PEDIDO | N1: Recepção | O1: ITEM | P1: CHAMADO | Q1: EDOA | R1: CENTRO DE CUSTO | S1: CONTA CONTÁBIL | T1: ENVIO PARA PAGAMENTO | U1: PAGO / Nº DOCUMENTO
A2: =IF(U2<>"","Pago",IF(T2<>"","Enviado para pagamento",IF(N2<>"","Pedido Recepcionado",IF(M2<>"","Pedido Concluído",IF(L2<>"","RC Criada","Lançar Pgto"))))) | B2: RDB - CONS | C2: Consumidor | D2: Interno | E2: 1001 | F2: Honorários | G2: 30000 | H2: Janeiro | I2: 05.02.2024 | J2: Fixo | K2: Honorários Consumidor janeiro | L2: 25001001 | M2: 4500001001 | N2: 180001001 | O2: 10 | P2: 1301001 | Q2: HONORÁRIOS E DESPESAS | R2: GI52000 | S2: 622600 | T2: 24.01.2024 | U2: 211401001
A3: =IF(U3<>"","Pago",IF(T3<>"","Enviado para pagamento",IF(N3<>"","Pedido Recepcionado",IF(M3<>"","Pedido Concluído",IF(L3<>"","RC Criada","Lançar Pgto"))))) | B3: RDB - CONS | C3: Consumidor | D3: Interno | E3: 1002 | F3: Condenação | G3: 40950.53 | H3: Janeiro | I3: 09.02.2024 | J3: Variável pontual | K3: Condenação Consumidor janeiro | L3: 25001002 | M3: 4500001002 | N3: 180001002 | O3: 10 | P3: 1301002 | Q3: CORPORATE | R3: GI52000 | S3: 622600 | T3: 24.01.2024 | U3: 211401002
A4: =IF(U4<>"","Pago",IF(T4<>"","Enviado para pagamento",IF(N4<>"","Pedido Recepcionado",IF(M4<>"","Pedido Concluído",IF(L4<>"","RC Criada","Lançar Pgto"))))) | B4: RDB - CONS | C4: Consumidor | D4: Interno | E4: 1003 | F4: Acordo | G4: 10091.98 | H4: Janeiro | I4: 23.02.2024 | J4: Variável pontual | K4: Acordo Consumidor janeiro | L4: 25001003 | M4: 4500001003 | N4: 180001003 | O4: 10 | P4: 1301003 | Q4: ACORDOS CONSUMIDOR | R4: GI52000 | S4: 622600 | T4: 14.01.2024 | U4: 211401003
A5: =IF(U5<>"","Pago",IF(T5<>"","Enviado para pagamento",IF(N5<>"","Pedido Recepcionado",IF(M5<>"","Pedido Concluído",IF(L5<>"","RC Criada","Lançar Pgto"))))) | B5: RDB - CONS | C5: Acordo Projeto SAC | D5: Interno | E5: 1004 | F5: Acordo | G5: 6501.7 | H5: Janeiro | I5: 11.02.2024 | J5: Variável pontual | K5: Acordo Acordo Projeto SAC janeiro | L5: 25001004 | M5: 4500001004 | N5: 180001004 | O5: 10 | P5: 1301004 | Q5: ACORDOS SAC | R5: GI52000 | S5: 622600 | T5: 08.01.2024 | U5: 211401004
A6: =IF(U6<>"","Pago",IF(T6<>"","Enviado para pagamento",IF(N6<>"","Pedido Recepcionado",IF(M6<>"","Pedido Concluído",IF(L6<>"","RC Criada","Lançar Pgto"))))) | B6: RDB - DIV | C6: Cível | D6: Interno | E6: 1005 | F6: Honorários | G6: 6400 | H6: Janeiro | I6: 22.02.2024 | J6: Fixo | K6: Honorários Cível janeiro | L6: 25001005 | M6: 4500001005 | N6: 180001005 | O6: 10 | P6: 1301005 | Q6: HONORÁRIOS E DESPESAS | R6: GI52000 | S6: 622600 | T6: 07.01.2024 | U6: 211401005
A7: =IF(U7<>"","Pago",IF(T7<>"","Enviado para pagamento",IF(N7<>"","Pedido Recepcionado",IF(M7<>"","Pedido Concluído",IF(L7<>"","RC Criada","Lançar Pgto"))))) | B7: RDB - DIV | C7: Cível | D7: ADIANTAMENTO | E7: 1006 | F7: Custas | G7: 977.77 | H7: Janeiro | I7: 12.02.2024 | J7: Variável pontual | K7: Custas Cível janeiro | L7: 25001006 | M7: 4500001006 | N7: 180001006 | O7: 10 | P7: 1301006 | Q7: HONORÁRIOS E DESPESAS | R7: GI52000 | S7: 622600 | T7: 15.01.2024 | U7: 211401006
A8: =IF(U8<>"","Pago",IF(T8<>"","Enviado para pagamento",IF(N8<>"","Pedido Recepcionado",IF(M8<>"","Pedido Concluído",IF(L8<>"","RC Criada","Lançar Pgto"))))) | B8: RDB - TRAB CVP | C8: Trabalhista | D8: Interno | E8: 1007 | F8: Condenação | G8: 25892.66 | H8: Janeiro | I8: 10.02.2024 | J8: Variável pontual | K8: Condenação Trabalhista janeiro | L8: 25001007 | M8: 4500001007 | N8: 180001007 | O8: 10 | P8: 1301007 | Q8: TRABALHISTA GERAL | R8: GI52000 | S8: 622600 | T8: 23.01.2024 | U8: 211401007
A9: =IF(U9<>"","Pago",IF(T9<>"","Enviado para pagamento",IF(N9<>"","Pedido Recepcionado",IF(M9<>"","Pedido Concluído",IF(L9<>"","RC Criada","Lançar Pgto"))))) | B9: RDB - TRAB CVP | C9: Trabalhista | D9: ADIANTAMENTO | E9: 1008 | F9: acordo | G9: 14535.69 | H9: Janeiro | I9: 09.02.2024 | J9: variável pontual | K9: acordo Trabalhista janeiro | L9: 25001008 | M9: 4500001008 | N9: 180001008 | O9: 10 | P9: 1301008 | Q9: TRABALHISTA GERAL | R9: GI52000 | S9: 622600 | T9: 07.01.2024 | U9: 211401008
A10: =IF(U10<>"","Pago",IF(T10<>"","Enviado para pagamento",IF(N10<>"","Pedido Recepcionado",IF(M10<>"","Pedido Concluído",IF(L10<>"","RC Criada","Lançar Pgto"))))) | B10: RDB - TRAB SUPORTE | C10: Trabalhista | D10: ADIANTAMENTO | E10: 1009 | F10: Acordo | G10: 10645.97 | H10: Janeiro | I10: 08.02.2024 | J10: Variável pontual | K10: Acordo Trabalhista janeiro | L10: 25001009 | M10: 4500001009 | N10: 180001009 | O10: 10 | P10: 1301009 | Q10: TRABALHISTA ACORDOS | R10: GI52000 | S10: 622600 | T10: 03.01.2024 | U10: 211401009
A11: =IF(U11<>"","Pago",IF(T11<>"","Enviado para pagamento",IF(N11<>"","Pedido Recepcionado",IF(M11<>"","Pedido Concluído",IF(L11<>"","RC Criada","Lançar Pgto"))))) | B11: RDB - TRAB PIF | C11: Trabalhista | D11: ADIANTAMENTO | E11: 1010 | F11: Acordo | G11: 19039.42 | H11: Janeiro | I11: 16.02.2024 | J11: Variável pontual | K11: Acordo Trabalhista janeiro | L11: 25001010 | M11: 4500001010 | N11: 180001010 | O11: 10 | P11: 1301010 | Q11: PIF/PDV | R11: GI52000 | S11: 622600 | T11: 20.01.2024 | U11: 211401010
A12: =IF(U12<>"","Pago",IF(T12<>"","Enviado para pagamento",IF(N12<>"","Pedido Recepcionado",IF(M12<>"","Pedido Concluído",IF(L12<>"","RC Criada","Lançar Pgto"))))) | B12: RDB - TRIB | C12: Tributário | D12: ADIANTAMENTO | E12: 1011 | F12: Honorários | G12: 17000 | H12: Janeiro | I12: 06.02.2024 | J12: Fixo | K12: Honorários Tributário janeiro | L12: 25001011 | M12: 4500001011 | N12: 180001011 | O12: 10 | P12: 1301011 | Q12: HONORÁRIOS E DESPESAS | R12: GI52000 | S12: 622600 | T12: 24.01.2024 | U12: 211401011
A13: =IF(U13<>"","Pago",IF(T13<>"","Enviado para pagamento",IF(N13<>"","Pedido Recepcionado",IF(M13<>"","Pedido Concluído",IF(L13<>"","RC Criada","Lançar Pgto"))))) | B13: RDB - TRIB | C13: Tributário | D13: Interno | E13: 1012 | F13: Custas | G13: 2951.31 | H13: Janeiro | I13: 17.02.2024 | J13: Variável pontual | K13: Custas Tributário janeiro | L13: 25001012 | M13: 4500001012 | N13: 180001012 | O13: 10 | P13: 1301012 | Q13: CORPORATE | R13: GI52000 | S13: 622600 | T13: 03.01.2024 | U13: 211401012
... A52: =IF(U52<>"","Pago",IF(T52<>"","Enviado para pagamento",IF(N52<>"","Pedido Recepcionado",IF(M52<>"","Pedido Concluído",IF(L52<>"","RC Criada","Lançar Pgto"))))) | B52: RDB - DIV | C52: Consumidor | D52: Interno | E52: 1051 | F52: Juros e correção | G52: 771.47 | H52: Março | I52: 27.04.2024 | J52: Variável pontual | K52: Juros e correção Consumidor março | L52: 25001051 | M52: 4500001051 | N52: 180001051 | O52: 10 | P52: 1301051 | Q52: OUTRA ÁREA | R52: GI52000 | S52: 622600 | T52: 10.03.2024 | U52: 211401051
A53: =IF(U53<>"","Pago",IF(T53<>"","Enviado para pagamento",IF(N53<>"","Pedido Recepcionado",IF(M53<>"","Pedido Concluído",IF(L53<>"","RC Criada","Lançar Pgto"))))) | B53: RDB - CONS | C53: Consumidor | D53: ADIANTAMENTO | E53: 1052 | F53: Honorários | G53: 30000 | H53: Abril | I53: 19.05.2024 | J53: Fixo | K53: Honorários Consumidor abril | L53: 25001052 | M53: 4500001052 | N53: 180001052 | O53: 10 | P53: 1301052 | Q53: HONORÁRIOS E DESPESAS | R53: GI52015 | S53: 622600
A54: =IF(U54<>"","Pago",IF(T54<>"","Enviado para pagamento",IF(N54<>"","Pedido Recepcionado",IF(M54<>"","Pedido Concluído",IF(L54<>"","RC Criada","Lançar Pgto"))))) | B54: RDB - CONS | C54: Consumidor | D54: Interno | E54: 1053 | F54: Condenação | G54: 52193.05 | H54: Abril | I54: 12.05.2024 | J54: Variável pontual | K54: Condenação Consumidor abril | L54: 25001053 | M54: 4500001053 | N54: 180001053 | O54: 10 | P54: 1301053 | Q54: CORPORATE | R54: GI52015 | S54: 622600
A55: =IF(U55<>"","Pago",IF(T55<>"","Enviado para pagamento",IF(N55<>"","Pedido Recepcionado",IF(M55<>"","Pedido Concluído",IF(L55<>"","RC Criada","Lançar Pgto"))))) | B55: RDB - CONS | C55: Consumidor | D55: Interno | E55: 1054 | F55: Acordo | G55: 10678.55 | H55: Abril | I55: 23.05.2024 | J55: Variável pontual | K55: Acordo Consumidor abril | L55: 25001054 | M55: 4500001054 | O55: 10 | P55: 1301054 | Q55: ACORDOS CONSUMIDOR | R55: GI52015 | S55: 622600
A56: =IF(U56<>"","Pago",IF(T56<>"","Enviado para pagamento",IF(N56<>"","Pedido Recepcionado",IF(M56<>"","Pedido Concluído",IF(L56<>"","RC Criada","Lançar Pgto"))))) | B56: RDB - CONS | C56: Acordo Projeto SAC | D56: Interno | E56: 1055 | F56: Acordo | G56: 8172.55 | H56: Abril | I56: 05.05.2024 | J56: Variável pontual | K56: Acordo Acordo Projeto SAC abril | L56: 25001055 | M56: 4500001055 | N56: 180001055 | O56: 10 | P56: 1301055 | Q56: ACORDOS SAC | R56: GI52015 | S56: 622600 | T56: 03.04.2024
A57: =IF(U57<>"","Pago",IF(T57<>"","Enviado para pagamento",IF(N57<>"","Pedido Recepcionado",IF(M57<>"","Pedido Concluído",IF(L57<>"","RC Criada","Lançar Pgto"))))) | B57: RDB - DIV | C57: Cível | D57: Interno | E57: 1056 | F57: Honorários | G57: 6400 | H57: Abril | I57: 12.05.2024 | J57: Fixo | K57: Honorários Cível abril | L57: 25001056 | M57: 4500001056 | N57: 180001056 | O57: 10 | P57: 1301056 | Q57: HONORÁRIOS E DESPESAS | R57: GI52015 | S57: 622600 | T57: 03.04.2024 | U57: 211401056
A58: =IF(U58<>"","Pago",IF(T58<>"","Enviado para pagamento",IF(N58<>"","Pedido Recepcionado",IF(M58<>"","Pedido Concluído",IF(L58<>"","RC Criada","Lançar Pgto"))))) | B58: RDB - DIV | C58: Cível | D58: Interno | E58: 1057 | F58: Custas | G58: 1045.95 | H58: Abril | I58: 21.05.2024 | J58: Variável pontual | K58: Custas Cível abril | L58: 25001057 | M58: 4500001057 | O58: 10 | P58: 1301057 | Q58: HONORÁRIOS E DESPESAS | R58: GI52015 | S58: 622600
A59: =IF(U59<>"","Pago",IF(T59<>"","Enviado para pagamento",IF(N59<>"","Pedido Recepcionado",IF(M59<>"","Pedido Concluído",IF(L59<>"","RC Criada","Lançar Pgto"))))) | B59: RDB - TRAB CVP | C59: Trabalhista | D59: ADIANTAMENTO | E59: 1058 | F59: Condenação | G59: 22380.05 | H59: Abril | I59: 11.05.2024 | J59: Variável pontual | K59: Condenação Trabalhista abril | L59: 25001058 | M59: 4500001058 | N59: 180001058 | O59: 10 | P59: 1301058 | Q59: TRABALHISTA GERAL | R59: GI52015 | S59: 622600 | T59: 18.04.2024 | U59: 211401058
A60: =IF(U60<>"","Pago",IF(T60<>"","Enviado para pagamento",IF(N60<>"","Pedido Recepcionado",IF(M60<>"","Pedido Concluído",IF(L60<>"","RC Criada","Lançar Pgto"))))) | B60: RDB - TRAB CVP | C60: Trabalhista | D60: ADIANTAMENTO | E60: 1059 | F60: acordo | G60: 12793.87 | H60: Abril | I60: 12.05.2024 | J60: variável pontual | K60: acordo Trabalhista abril | L60: 25001059 | M60: 4500001059 | N60: 180001059 | O60: 10 | P60: 1301059 | Q60: TRABALHISTA GERAL | R60: GI52015 | S60: 622600 | T60: 26.04.2024
A61: =IF(U61<>"","Pago",IF(T61<>"","Enviado para pagamento",IF(N61<>"","Pedido Recepcionado",IF(M61<>"","Pedido Concluído",IF(L61<>"","RC Criada","Lançar Pgto"))))) | B61: RDB - TRAB SUPORTE | C61: Trabalhista | D61: Interno | E61: 1060 | F61: Acordo | G61: 8902.7 | H61: Abril | I61: 08.05.2024 | J61: Variável pontual | K61: Acordo Trabalhista abril | L61: 25001060 | M61: 4500001060 | N61: 180001060 | O61: 10 | P61: 1301060 | Q61: TRABALHISTA ACORDOS | R61: GI52015 | S61: 622600
A62: =IF(U62<>"","Pago",IF(T62<>"","Enviado para pagamento",IF(N62<>"","Pedido Recepcionado",IF(M62<>"","Pedido Concluído",IF(L62<>"","RC Criada","Lançar Pgto"))))) | B62: RDB - TRAB PIF | C62: Trabalhista | D62: ADIANTAMENTO | E62: 1061 | F62: Acordo | G62: 16775.45 | H62: Abril | I62: 18.05.2024 | J62: Variável pontual | K62: Acordo Trabalhista abril | L62: 25001061 | M62: 4500001061 | N62: 180001061 | O62: 10 | P62: 1301061 | Q62: PIF/PDV | R62: GI52015 | S62: 622600
A63: =IF(U63<>"","Pago",IF(T63<>"","Enviado para pagamento",IF(N63<>"","Pedido Recepcionado",IF(M63<>"","Pedido Concluído",IF(L63<>"","RC Criada","Lançar Pgto"))))) | B63: RDB - TRIB | C63: Tributário | D63: ADIANTAMENTO | E63: 1062 | F63: Honorários | G63: 17000 | H63: Abril | I63: 28.05.2024 | J63: Fixo | K63: Honorários Tributário abril | L63: 25001062 | M63: 4500001062 | N63: 180001062 | O63: 10 | P63: 1301062 | Q63: HONORÁRIOS E DESPESAS | R63: GI52015 | S63: 622600
A64: =IF(U64<>"","Pago",IF(T64<>"","Enviado para pagamento",IF(N64<>"","Pedido Recepcionado",IF(M64<>"","Pedido Concluído",IF(L64<>"","RC Criada","Lançar Pgto"))))) | B64: RDB - TRIB | C64: Tributário | D64: Interno | E64: 1063 | F64: Custas | G64: 2465.01 | H64: Abril | I64: 06.05.2024 | J64: Variável pontual | K64: Custas Tributário abril | L64: 25001063 | M64: 4500001063 | N64: 180001063 | O64: 10 | P64: 1301063 | Q64: CORPORATE | R64: GI52015 | S64: 622600 | T64: 13.04.2024 | U64: 211401063
A65: =IF(U65<>"","Pago",IF(T65<>"","Enviado para pagamento",IF(N65<>"","Pedido Recepcionado",IF(M65<>"","Pedido Concluído",IF(L65<>"","RC Criada","Lançar Pgto"))))) | B65: RDB - DIV | C65: LGPD | D65: ADIANTAMENTO | E65: 1064 | F65: Honorários | G65: 12000 | H65: Abril | I65: 08.05.2024 | J65: Fixo | K65: Honorários LGPD abril | L65: 25001064 | M65: 4500001064 | N65: 180001064 | O65: 10 | P65: 1301064 | Q65: LGPD GERAL & TERCEIROS | R65: GI52015 | S65: 622600 | T65: 08.04.2024 | U65: 211401064
A66: =IF(U66<>"","Pago",IF(T66<>"","Enviado para pagamento",IF(N66<>"","Pedido Recepcionado",IF(M66<>"","Pedido Concluído",IF(L66<>"","RC Criada","Lançar Pgto"))))) | B66: RDB - DIV | C66: LGPD | D66: ADIANTAMENTO | E66: 1065 | F66: LGPD | G66: 2191.59 | H66: Abril | I66: 09.05.2024 | J66: Variável pontual | K66: LGPD LGPD abril | L66: 25001065 | M66: 4500001065 | N66: 180001065 | O66: 10 | P66: 1301065 | Q66: LGPD GERAL & TERCEIROS | R66: GI52015 | S66: 622600 | T66: 14.04.2024
A67: =IF(U67<>"","Pago",IF(T67<>"","Enviado para pagamento",IF(N67<>"","Pedido Recepcionado",IF(M67<>"","Pedido Concluído",IF(L67<>"","RC Criada","Lançar Pgto"))))) | B67: RDB - DIV | C67: Cartório | D67: Interno | E67: 1066 | F67: Despesas | G67: 1310.09 | H67: Abril | I67: 07.05.2024 | J67: Fixo valor variável | K67: Despesas Cartório abril | L67: 25001066 | M67: 4500001066 | N67: 180001066 | O67: 10 | P67: 1301066 | Q67: CARTÓRIO | R67: GI52015 | S67: 622600
A68: =IF(U68<>"","Pago",IF(T68<>"","Enviado para pagamento",IF(N68<>"","Pedido Recepcionado",IF(M68<>"","Pedido Concluído",IF(L68<>"","RC Criada","Lançar Pgto"))))) | B68: RDB - DIV | C68: Projuris SUPRAMONTE | D68: Interno | E68: 1067 | F68: Projuris | G68: 2068.72 | H68: Abril | I68: 06.05.2024 | J68: Fixo | K68: Projuris Projuris SUPRAMONTE abril | L68: 25001067 | M68: 4500001067 | N68: 180001067 | O68: 10 | P68: 1301067 | Q68: SISTEMAS | R68: GI52015 | S68: 622600
A69: =IF(U69<>"","Pago",IF(T69<>"","Enviado para pagamento",IF(N69<>"","Pedido Recepcionado",IF(M69<>"","Pedido Concluído",IF(L69<>"","RC Criada","Lançar Pgto"))))) | B69: RDB - DIV | C69: Consumidor | D69: Interno | E69: 1068 | F69: Juros e correção | G69: 742.6 | H69: Abril | I69: 07.05.2024 | J69: Variável pontual | K69: Juros e correção Consumidor abril | L69: 25001068 | M69: 4500001068 | N69: 180001068 | O69: 10 | P69: 1301068 | Q69: OUTRA ÁREA | R69: GI52015 | S69: 622600 | T69: 25.04.2024
A70: =IF(U70<>"","Pago",IF(T70<>"","Enviado para pagamento",IF(N70<>"","Pedido Recepcionado",IF(M70<>"","Pedido Concluído",IF(L70<>"","RC Criada","Lançar Pgto"))))) | B70: RDB - CONS | C70: Consumidor | D70: Interno | E70: 1069 | F70: Honorários | G70: 30000 | H70: Maio | I70: 18.06.2024 | J70: Fixo | K70: Honorários Consumidor maio | L70: 25001069 | O70: 10 | P70: 1301069 | Q70: HONORÁRIOS E DESPESAS | R70: GI52000 | S70: 622600
A71: =IF(U71<>"","Pago",IF(T71<>"","Enviado para pagamento",IF(N71<>"","Pedido Recepcionado",IF(M71<>"","Pedido Concluído",IF(L71<>"","RC Criada","Lançar Pgto"))))) | B71: RDB - CONS | C71: Consumidor | D71: ADIANTAMENTO | E71: 1070 | F71: Condenação | G71: 44741.54 | H71: Maio | I71: 06.06.2024 | J71: Variável pontual | K71: Condenação Consumidor maio | L71: 25001070 | O71: 10 | P71: 1301070 | Q71: CORPORATE | R71: GI52000 | S71: 622600
A72: =IF(U72<>"","Pago",IF(T72<>"","Enviado para pagamento",IF(N72<>"","Pedido Recepcionado",IF(M72<>"","Pedido Concluído",IF(L72<>"","RC Criada","Lançar Pgto"))))) | B72: RDB - CONS | C72: Consumidor | D72: ADIANTAMENTO | E72: 1071 | F72: Acordo | G72: 10390.26 | H72: Maio | I72: 13.06.2024 | J72: Variável pontual | K72: Acordo Consumidor maio | O72: 10 | Q72: ACORDOS CONSUMIDOR | R72: GI52000 | S72: 622600
A73: =IF(U73<>"","Pago",IF(T73<>"","Enviado para pagamento",IF(N73<>"","Pedido Recepcionado",IF(M73<>"","Pedido Concluído",IF(L73<>"","RC Criada","Lançar Pgto"))))) | B73: RDB - CONS | C73: Acordo Projeto SAC | D73: ADIANTAMENTO | E73: 1072 | F73: Acordo | G73: 9364.86 | H73: Maio | I73: 18.06.2024 | J73: Variável pontual | K73: Acordo Acordo Projeto SAC maio | L73: 25001072 | M73: 4500001072 | N73: 180001072 | O73: 10 | P73: 1301072 | Q73: ACORDOS SAC | R73: GI52000 | S73: 622600
A74: =IF(U74<>"","Pago",IF(T74<>"","Enviado para pagamento",IF(N74<>"","Pedido Recepcionado",IF(M74<>"","Pedido Concluído",IF(L74<>"","RC Criada","Lançar Pgto"))))) | B74: RDB - DIV | C74: Cível | D74: ADIANTAMENTO | E74: 1073 | F74: Honorários | G74: 6400 | H74: Maio | I74: 09.06.2024 | J74: Fixo | K74: Honorários Cível maio | L74: 25001073 | M74: 4500001073 | N74: 180001073 | O74: 10 | P74: 1301073 | Q74: HONORÁRIOS E DESPESAS | R74: GI52000 | S74: 622600 | T74: 07.05.2024 | U74: 211401073
A75: =IF(U75<>"","Pago",IF(T75<>"","Enviado para pagamento",IF(N75<>"","Pedido Recepcionado",IF(M75<>"","Pedido Concluído",IF(L75<>"","RC Criada","Lançar Pgto"))))) | B75: RDB - DIV | C75: Cível | D75: Interno | E75: 1074 | F75: Custas | G75: 826.81 | H75: Maio | I75: 28.06.2024 | J75: Variável pontual | K75: Custas Cível maio | O75: 10 | Q75: HONORÁRIOS E DESPESAS | R75: GI52000 | S75: 622600
A76: =IF(U76<>"","Pago",IF(T76<>"","Enviado para pagamento",IF(N76<>"","Pedido Recepcionado",IF(M76<>"","Pedido Concluído",IF(L76<>"","RC Criada","Lançar Pgto"))))) | B76: RDB - TRAB CVP | C76: Trabalhista | D76: ADIANTAMENTO | E76: 1075 | F76: Condenação | G76: 23136.05 | H76: Maio | I76: 21.06.2024 | J76: Variável pontual | K76: Condenação Trabalhista maio | O76: 10 | Q76: TRABALHISTA GERAL | R76: GI52000 | S76: 622600
A77: =IF(U77<>"","Pago",IF(T77<>"","Enviado para pagamento",IF(N77<>"","Pedido Recepcionado",IF(M77<>"","Pedido Concluído",IF(L77<>"","RC Criada","Lançar Pgto"))))) | B77: RDB - TRAB CVP | C77: Trabalhista | D77: Interno | E77: 1076 | F77: acordo | G77: 17516.32 | H77: Maio | I77: 06.06.2024 | J77: variável pontual | K77: acordo Trabalhista maio | L77: 25001076 | M77: 4500001076 | N77: 180001076 | O77: 10 | P77: 1301076 | Q77: TRABALHISTA GERAL | R77: GI52000 | S77: 622600 | T77: 17.05.2024
A78: =IF(U78<>"","Pago",IF(T78<>"","Enviado para pagamento",IF(N78<>"","Pedido Recepcionado",IF(M78<>"","Pedido Concluído",IF(L78<>"","RC Criada","Lançar Pgto"))))) | B78: RDB - TRAB SUPORTE | C78: Trabalhista | D78: Interno | E78: 1077 | F78: Acordo | G78: 7488.4 | H78: Maio | I78: 24.06.2024 | J78: Variável pontual | K78: Acordo Trabalhista maio | L78: 25001077 | O78: 10 | P78: 1301077 | Q78: TRABALHISTA ACORDOS | R78: GI52000 | S78: 622600
...

Sheet RAP PAGAMENTOS
B2: MÊS FECHAMENTO | C2: 2 | I2: consumidor
B3: RESTOS A PAGAR POR MÊS
B4: EDOA | C4: ÁREA | D4: BUDGET ANUAL | E4: PREVISTO | F4: REALIZADO | G4: GAP | H4: BUDGET RESTANTE
B5: OUTROS (Jurídico) | D5: 60000 | E5: =(D5/12)*$C$2 | F5: =SUMIF('Controle Lançamentos'!Q:Q,'RAP PAGAMENTOS'!B5,'Controle Lançamentos'!G:G) | G5: =E5-F5 | H5: =D5-F5
B6: CARTÓRIO | D6: 140000 | E6: =(D6/12)*$C$2 | F6: =SUMIF('Controle Lançamentos'!Q:Q,'RAP PAGAMENTOS'!B6,'Controle Lançamentos'!G:G) | G6: =E6-F6 | H6: =D6-F6
B7: SISTEMAS | D7: 60000 | E7: =(D7/12)*$C$2 | F7: 3 | G7: =E7-F7 | H7: =D7-F7
B8: SISTEMAS | C8: Projuris SUPRAMONTE | D8: 30000 | E8: =(D8/12)*$C$2 | F8: =SUMIFS('Controle Lançamentos'!G:G,'Controle Lançamentos'!C:C,'RAP PAGAMENTOS'!C8,'Controle Lançamentos'!Q:Q,'RAP PAGAMENTOS'!$B$7) | G8: =E8-F8 | H8: =D8-F8
B9: HONORÁRIOS E DESPESAS | D9: 1500000 | E9: =(D9/12)*$C$2 | F9: =SUMIF('Controle Lançamentos'!Q:Q,'RAP PAGAMENTOS'!B9,'Controle Lançamentos'!G:G) | G9: =E9-F9 | H9: =D9-F9
B10: HONORÁRIOS E DESPESAS | C10: Cível | D10: 90000 | E10: =(D10/12)*$C$2 | F10: =SUMIFS('Controle Lançamentos'!G:G,'Controle Lançamentos'!C:C,'RAP PAGAMENTOS'!C10,'Controle Lançamentos'!Q:Q,'RAP PAGAMENTOS'!$B$9) | G10: =E10-F10 | H10: =D10-F10
B11: HONORÁRIOS E DESPESAS | C11: Consumidor | D11: 400000 | E11: =(D11/12)*$C$2 | F11: =SUMIFS('Controle Lançamentos'!G:G,'Controle Lançamentos'!C:C,'RAP PAGAMENTOS'!C11,'Controle Lançamentos'!Q:Q,'RAP PAGAMENTOS'!$B$9) | G11: =E11-F11 | H11: =D11-F11
B12: HONORÁRIOS E DESPESAS | C12: Tributário | D12: 210000 | E12: =(D12/12)*$C$2 | F12: =SUMIFS('Controle Lançamentos'!G:G,'Controle Lançamentos'!C:C,'RAP PAGAMENTOS'!C12,'Controle Lançamentos'!Q:Q,'RAP PAGAMENTOS'!$B$9) | G12: =E12-F12 | H12: =D12-F12
B13: PIF/PDV | D13: 150000 | E13: =(D13/12)*$C$2 | F13: =SUMIF('Controle Lançamentos'!Q:Q,'RAP PAGAMENTOS'!B13,'Controle Lançamentos'!G:G) | G13: =E13-F13 | H13: =D13-F13
B14: CORPORATE | D14: 700000 | E14: =(D14/12)*$C$2 | F14: =SUMIF('Controle Lançamentos'!Q:Q,'RAP PAGAMENTOS'!B14,'Controle Lançamentos'!G:G) | G14: =E14-F14 | H14: =D14-F14
B15: CORPORATE | C15: Consumidor - Condenação | D15: 600000 | E15: =(D15/12)*$C$2 | F15: =SUMIFS('Controle Lançamentos'!G:G,'Controle Lançamentos'!C:C,"consumidor",'Controle Lançamentos'!Q:Q,'RAP PAGAMENTOS'!$B$14) | G15: =E15-F15 | H15: =D15-F15
B16: ACORDOS CONSUMIDOR | C16: Consumidor - Acordo | D16: 100000 | E16: =(D16/12)*$C$2 | F16: =SUMIFS('Controle Lançamentos'!G:G,'Controle Lançamentos'!C:C,'RAP PAGAMENTOS'!I2,'Controle Lançamentos'!Q:Q,'RAP PAGAMENTOS'!$B$16) | G16: =E16-F16 | H16: =D16-F16
B17: ACORDOS SAC | C17: Consumidor - Projeto SAC | D17: 60000 | E17: =(D17/12)*$C$2 | F17: =SUMIFS('Controle Lançamentos'!G:G,'Controle Lançamentos'!C:C,"Acordo Projeto SAC",'Controle Lançamentos'!Q:Q,'RAP PAGAMENTOS'!$B$17) | G17: =E17-F17 | H17: =D17-F17
B18: TRIBUTÁRIO | C18: Tributário | D18: 20000 | E18: =(D18/12)*$C$2 | F18: =SUMIFS('Controle Lançamentos'!G:G,'Controle Lançamentos'!C:C,'RAP PAGAMENTOS'!C18,'Controle Lançamentos'!Q:Q,'RAP PAGAMENTOS'!$B$14) | G18: =E18-F18 | H18: =D18-F18
B19: DEPÓSITO JUDICIAL | D19: 0 | E19: =(D19/12)*$C$2 | F19: =SUMIFS('Controle Lançamentos'!G:G,'Controle Lançamentos'!C:C,'RAP PAGAMENTOS'!C19,'Controle Lançamentos'!Q:Q,'RAP PAGAMENTOS'!$B$14) | G19: =E19-F19 | H19: =D19-F19
B20: DEPÓSITO JUDICIAL | C20: Consumidor | D20: 0 | E20: =(D20/12)*$C$2 | F20: =SUMIFS('Controle Lançamentos'!G:G,'Controle Lançamentos'!C:C,'RAP PAGAMENTOS'!C20,'Controle Lançamentos'!Q:Q,'RAP PAGAMENTOS'!$B$14) | G20: =E20-F20 | H20: =D20-F20
B21: LGPD GERAL & TERCEIROS | C21: LGPD | D21: 200000 | E21: =(D21/12)*$C$2 | F21: =SUMIF('Controle Lançamentos'!Q:Q,'RAP PAGAMENTOS'!B21,'Controle Lançamentos'!G:G) | G21: =E21-F21 | H21: =D21-F21
B22: TRABALHISTA ACORDOS | C22: Trabalhista | D22: 80000 | E22: =(D22/12)*$C$2 | F22: =SUMIF('Controle Lançamentos'!Q:Q,'RAP PAGAMENTOS'!B22,'Controle Lançamentos'!G:G) | G22: =E22-F22 | H22: =D22-F22
B23: TRABALHISTA GERAL | C23: Trabalhista | D23: 1100000 | E23: =(D23/12)*$C$2 | F23: =SUMIF('Controle Lançamentos'!Q:Q,'RAP PAGAMENTOS'!B23,'Controle Lançamentos'!G:G) | G23: =E23-F23 | H23: =D23-F23
B30: HONORÁRIOS E DESPESAS
B31: ÁREA | D31: BUDGET ANUAL | E31: PREVISTO | F31: REAL TOTAL | G31: GAP | H31: BUDGET RESTANTE | I31: BUDGET VARIÁVEL | J31: PREVISTO VARIÁVEL | K31: REAL VARIÁVEL | L31: GAP VARIÁVEL | M31: RESTANTE VARIÁVEL ATÉ DEZ | N31: BUDGET FIXO | O31: PREVISTO FIXO | P31: REAL FIXO | Q31: GAP FIXO | R31: RESTANTE FIXO ATÉ DEZ
B32: Cível | C32: Cível | D32: 90000 | E32: =(D32/12)*$C$2 | F32: =SUMIFS('Controle Lançamentos'!G:G,'Controle Lançamentos'!C:C,'RAP PAGAMENTOS'!B32,'Controle Lançamentos'!Q:Q,'RAP PAGAMENTOS'!$B$9) | G32: =E32-F32 | H32: =D32-F32 | I32: 20000 | J32: =(I32/12)*$C$2 | K32: =SUMIFS('Controle Lançamentos'!G:G,'Controle Lançamentos'!C:C,'RAP PAGAMENTOS'!B32,'Controle Lançamentos'!Q:Q,'RAP PAGAMENTOS'!$B$9,'Controle Lançamentos'!J:J,"Variável") | L32: =J32-K32 | M32: =I32-K32 | N32: 70000 | O32: =(N32/12)*$C$2 | P32: =SUMIFS('Controle Lançamentos'!G:G,'Controle Lançamentos'!C:C,'RAP PAGAMENTOS'!B32,'Controle Lançamentos'!Q:Q,'RAP PAGAMENTOS'!$B$9,'Controle Lançamentos'!J:J,"Fixo") | Q32: =O32-P32 | R32: =N32-P32
B33: Consumidor | C33: Consumidor | D33: 400000 | E33: =(D33/12)*$C$2 | F33: =SUMIFS('Controle Lançamentos'!G:G,'Controle Lançamentos'!C:C,'RAP PAGAMENTOS'!B33,'Controle Lançamentos'!Q:Q,'RAP PAGAMENTOS'!$B$9) | G33: =E33-F33 | H33: =D33-F33 | I33: 40000 | J33: =(I33/12)*$C$2 | K33: =SUMIFS('Controle Lançamentos'!G:G,'Controle Lançamentos'!C:C,'RAP PAGAMENTOS'!B33,'Controle Lançamentos'!Q:Q,'RAP PAGAMENTOS'!$B$9,'Controle Lançamentos'!J:J,"Variável") | L33: =J33-K33 | M33: =I33-K33 | N33: 360000 | O33: =(N33/12)*$C$2 | P33: =SUMIFS('Controle Lançamentos'!G:G,'Controle Lançamentos'!C:C,'RAP PAGAMENTOS'!B33,'Controle Lançamentos'!Q:Q,'RAP PAGAMENTOS'!$B$9,'Controle Lançamentos'!J:J,"Fixo") | Q33: =O33-P33 | R33: =N33-P33
B34: Tributário | C34: Tributário | D34: 210000 | E34: =(D34/12)*$C$2 | F34: =SUMIFS('Controle Lançamentos'!G:G,'Controle Lançamentos'!C:C,'RAP PAGAMENTOS'!B34,'Controle Lançamentos'!Q:Q,'RAP PAGAMENTOS'!$B$9) | G34: =E34-F34 | H34: =D34-F34 | I34: 6000 | J34: =(I34/12)*$C$2 | K34: =SUMIFS('Controle Lançamentos'!G:G,'Controle Lançamentos'!C:C,'RAP PAGAMENTOS'!B34,'Controle Lançamentos'!Q:Q,'RAP PAGAMENTOS'!$B$9,'Controle Lançamentos'!J:J,"Variável") | L34: =J34-K34 | M34: =I34-K34 | N34: 204000 | O34: =(N34/12)*$C$2 | P34: =SUMIFS('Controle Lançamentos'!G:G,'Controle Lançamentos'!C:C,'RAP PAGAMENTOS'!B34,'Controle Lançamentos'!Q:Q,'RAP PAGAMENTOS'!$B$9,'Controle Lançamentos'!J:J,"Fixo") | Q34: =O34-P34 | R34: =N34-P34

Sheet Adiantamentos
A1: Status | B1: Ok na Planilha de pagamentos | C1: Área | D1: Valor | E1: Chamado do adiantamento | F1: DOA | G1: Nº chamado da baixa | H1: Valor Excedente | I1: Valor total do adiantamento | J1: Baixa do Adiantamento | L1: Escritório
A2: =IF(J2<>"","Adiantamento Baixado",IF(G2<>"","Baixa lançada",IF(E2<>"","Adiantamento Lançado","Lançar adiantamento"))) | B2: Ok | C2: Trabalhista | D2: 500000 | E2: 1317001 | F2: TRABALHISTA | G2: 1345001 | H2: 1200.5 | I2: =D2+H2 | J2: 294918001 | L2: Escritório Alfa Advogados
A3: =IF(J3<>"","Adiantamento Baixado",IF(G3<>"","Baixa lançada",IF(E3<>"","Adiantamento Lançado","Lançar adiantamento"))) | B3: Ok | C3: Consumidor | D3: 300000 | E3: 1322002 | F3: CORPORATE | G3: 1343002 | H3: 0 | I3: =D3+H3 | L3: Beta & Associados
A4: =IF(J4<>"","Adiantamento Baixado",IF(G4<>"","Baixa lançada",IF(E4<>"","Adiantamento Lançado","Lançar adiantamento"))) | C4: Consumidor | D4: 250000 | E4: 1399003 | F4: CORPORATE | H4: 0 | I4: =D4+H4 | L4: Gama Consultoria Jurídica
A5: =IF(J5<>"","Adiantamento Baixado",IF(G5<>"","Baixa lançada",IF(E5<>"","Adiantamento Lançado","Lançar adiantamento"))) | C5: Trabalhista | D5: 150000 | F5: TRABALHISTA | H5: 0 | I5: =D5+H5 | L5: Delta Advocacia

Sheet Honorarios Variaveis 
A2: DOA | B2: ÁREA | C2: DETALHAMENTO | D2: RECORRÊNCIA | E2: JAN | F2: FEV | G2: MAR | H2: ABR | I2: MAI | J2: JUN | K2: JUL | L2: AGO | M2: SET | N2: OUT | O2: NOV | P2: DEZ | Q2: BUDGET | R2: REAL | S2: SALDO
A3: HONORÁRIOS E DESPESAS | B3: Tributário | C3: Honorários tributário fixo mensal | D3: Fixo | E3: 17000 | F3: 17000 | G3: 17000 | H3: 17000 | I3: 17000 | J3: 17000 | K3: 17000 | L3: 17000 | M3: 17000 | N3: 17000 | O3: 17000 | P3: 17000 | Q3: 204000 | R3: =SUMIFS('Controle Lançamentos'!G:G,'Controle Lançamentos'!#REF!,'Honorarios Variaveis '!#REF!) | S3: =Q3-R3
A4: HONORÁRIOS E DESPESAS | B4: Consumidor | C4: Acompanhamento carteira consumidor | D4: Fixo | E4: 30000 | F4: 30000 | G4: 30000 | H4: 30000 | I4: 30000 | J4: 30000 | K4: 30000 | L4: 30000 | M4: 30000 | N4: 30000 | O4: 30000 | P4: 30000 | Q4: 360000 | R4: =SUMIFS('Controle Lançamentos'!G:G,'Controle Lançamentos'!#REF!,'Honorarios Variaveis '!#REF!) | S4: =Q4-R4
A5: HONORÁRIOS E DESPESAS | B5: Consumidor | C5: Mão de obra terceirizada | D5: Fixo | E5: =2500.5 | F5: =2500.5 | G5: =2500.5 | H5: =2500.5 | I5: =2500.5 | J5: =2500.5 | K5: =2500.5 | L5: =2500.5 | ... P5: =2500.5 | Q5: 30006 | R5: =SUMIFS('Controle Lançamentos'!G:G,'Controle Lançamentos'!#REF!,'Honorarios Variaveis '!#REF!) | S5: =Q5-R5
A6: HONORÁRIOS E DESPESAS | B6: Cível | C6: Honorários cível fixo mensal | D6: Fixo | E6: 6400 | F6: 6400 | G6: 6400 | H6: 6400 | I6: 6400 | J6: 6400 | K6: 6400 | L6: 6400 | M6: 6400 | N6: 6400 | O6: 6400 | P6: 6400 | Q6: 76800 | R6: =SUMIFS('Controle Lançamentos'!G:G,'Controle Lançamentos'!#REF!,'Honorarios Variaveis '!#REF!) | S6: =Q6-R6
A7: HONORÁRIOS E DESPESAS | B7: Cível | C7: Êxito cível | D7: Variável pontual | E7: 0 | F7: 0 | G7: 0 | H7: 5000 | I7: 5000 | J7: 5000 | K7: 0 | L7: 0 | M7: 0 | N7: 5000 | O7: 0 | P7: 0 | Q7: 20000 | R7: =SUMIFS('Controle Lançamentos'!G:G,'Controle Lançamentos'!#REF!,'Honorarios Variaveis '!#REF!) | S7: =Q7-R7

Sheet Mensais
A1: Àrea | B1: Recorrência | C1: Valor Mensal | D1: Anual | E1: TRIMESTRAL | F1: MÉDIA VARIAVEIS | G1: Área | H1: Escritório | I1: Valor | K1: Area | L1: Valor | M1: Anual
A2: Consumidor | B2: Fixo | C2: 30000 | D2: 360000 | K2: Projuris | L2: 2068.72 | M2: 24824.64 | N2: Mensal sistema jurídico
A3: Consumidor | B3: Fixo | C3: 30000 | D3: 360000 | K3: Implantação | L3: 5000 | M3: 5000 | N3: Parcela única
A4: Tributário | B4: Fixo | C4: 17000 | D4: 204000
A5: Cível | B5: Fixo | C5: 6400 | D5: 76800

Sheet Devoluções
A1: ÁREA | B1: FORNECEDOR | C1: CÓDIGO DO BANCO | D1: DATA TRANSF/ | E1: PASTA BENNER | F1: VALOR DEVOLVIDO | G1: Nº CHAMADO | H1: DOCUMENTO | I1: OBSERVAÇÃO
A2: Consumidor | B2: Escritório Alfa Advogados | C2: 556159 | D2: 45315 | E2: Projuris 101 | F2: 12000.4 | G2: 1339001 | H2: 294905001 | I2: RECLASSIFICAR PARA DOA | L2: Consumidor | M2: =SUMIF(A:A,L2,F:F)
A3: Trabalhista | B3: Beta & Associados | C3: 556159 | D3: 45334 | E3: Projuris 102 | F3: 5300 | G3: 1341002 | H3: 294906002

Sheet RF MENSAL
A3: Jurídico | B3: FADM | C3: GI52000 | D3: 635110 | E3: Despesas com Estudos e Honorários
A4: Jurídico | B4: FADM | C4: GI52000 | D4: 622600 | E4: Honorários advocatícios
A5: Jurídico | B5: FADM | C5: GI52015 | D5: 611205 | E5: Acordos trabalhistas
